Workbook

Sheet GP Targets - Q2 2026
A1: Account (OT) | B1: Q1 2026 Notes | C1: Scheduled GP Q2 26 | D1: Q2 26 GP Target | E1: If drop - Reason
A2: Accurate Electronics
A3: Acuity Brands
A4: Alstom | C4: 81075
A5: BENCHMARK ELECTRONICS
A6: Bell Flight Textron Inc.
A7: CTCT
A8: Canyon AeroConnect
A9: Crane Aerospace & Electronics
A10: Eastman Kodak Company
A11: Emerald EMS | B11: Connected to Saline.
A12: Foxconn
A13: GE Healthcare
A14: GE MDS LLC
A15: GE Multilin | B15: Related to GE Vernova
A16: GE Vernova (Energy Businesses)
A17: General Motors
A18: Mars International Inc. | B18: CM for nonlimits, likely a smaller CM.
A19: Mirian Solutions
A20: Morey Corporation
A21: Ontic
A22: Projects Unlimited Inc. | C22: 9295
A23: Qual-Pro Corporation | C23: 1291
A24: S&B Industry, Inc. | B24: New
A25: Saline Lectronics Manufacturing Services
A26: SensIT | B26: Watch List
A27: noLimits Enterprises Inc (dba Radenso)
B29: Scheduled GP as of 4/08/26 | C29: =SUM(C2:C27) -> 91661 | D29: =SUM(D2:D27) -> 0
B30: GP Goal Q2 2026 | C30: 120000 | D30: =D29-C30 -> -120000

Sheet Aaron - Q2 2026
A1: Q1 2026 | O1: Q2 2026
A2: Status | B2: Account (OT) | C2: Account INFOR | D2: Locations | E2: Activities | F2: RFQ Lines | G2: CQ Lines | H2: CQ Lines Won | I2: Conversion Rate | J2: Booked GP | K2: Invoiced GP | L2: B to I | M2: % of Inv Total | N2: Q1 2026 Notes | O2: Scheduled GP | P2: GP Target | Q2: Q2 2026 Strategy
A3: Assigned | B3: Alstom | C3: Alstom Transportation Inc. | D3: 2 | E3: 2 | F3: 12 | G3: 18 | H3: 9 | I3: =H3/G3 -> 0.5 | J3: 9036.0122 | K3: =IFERROR(VLOOKUP(C3,'Q2 Data'!$P$3:$R$14,3,FALSE),"") -> 6034.61 | L3: =J3/K3 -> 1.4973647 | N3: Sold them ovens. Astute is now a pass thru. Purchasing department is all by projects and 'hand to mouth'. Very small, but able to pay the markups. Good traction with one Buyer. Vendor consolidation is the big focus. Working for a site in IL. 12+ Buyers. | O3: 81075 | P3: 115000 | Q3: Working to get setup as a supplier on record for many lines. Starting to see some rebuys. One key champion working with it.
A4: Assigned | B4: GE Healthcare | D4: 6 | E4: 12 | F4: 9 | G4: 4 | H4: 2 | I4: =H4/G4 -> 0.5 | J4: =IFERROR(VLOOKUP(C4,'Q2 Data'!$Y$3:$Z$12,2,FALSE),"") | K4: =IFERROR(VLOOKUP(C4,'Q2 Data'!$P$3:$R$14,3,FALSE),"") | N4: Just got approved with their repairs division to get into other Bus. | P4: 10000 | Q4: Visted in March and met the whole team. New order for $600 today. Repair. Second site, able to use refrubs. Quick feedback.
A5: Assigned | B5: Qual-Pro Corporation | C5: Qual-Pro Corporation | D5: 2 | E5: 1 | F5: 10 | G5: 3 | H5: 2 | I5: =H5/G5 -> 0.66666667 | J5: =IFERROR(VLOOKUP(C5,'Q2 Data'!$Y$3:$Z$12,2,FALSE),"") -> 2013.95 | K5: =IFERROR(VLOOKUP(C5,'Q2 Data'!$P$3:$R$14,3,FALSE),"") -> 1524.85 | L5: =J5/K5 -> 1.3207529 | N5: Related to Ontic. L3 is one of their customers. Leveraging Ontic. | O5: 1291 | P5: 15000 | Q5: Liz visiting CA in May, pushing for a meeting.
A6: Assigned | B6: Morey Corporation | C6: THE MOREY CORPORATION | D6: 1 | E6: 15 | F6: 26 | G6: 4 | H6: 1 | I6: =H6/G6 -> 0.25 | J6: =IFERROR(VLOOKUP(C6,'Q2 Data'!$Y$3:$Z$12,2,FALSE),"") -> 9374.408 | K6: =IFERROR(VLOOKUP(C6,'Q2 Data'!$P$3:$R$14,3,FALSE),"") -> 0 | L6: =J6/K6 -> #DIV/0! | N6: Prioritized net terms with them. Making sure they pay on time. Analog Devices have a large price increase coming, looking to see how we can help them keep costs down. Also, TI is in a smiliar boat. | P6: 15000 | Q6: Work lists for Morey. Buyer just told Aaron to stop reaching out, 1-2X a week is too much. Sending proactive offers. Keep reach outs exactly for what they need. Fell behind on two invoices, accounting is current now. N120. Just visited them in March. Astute can do quality in-house. Jason is overwhlemed. Cost savings is not as urgent, more urgent is making sure they have what they need first. Asked for last look.
A7: Assigned | B7: Projects Unlimited Inc. | C7: Projects Unlimited Inc. | D7: 3 | E7: 5 | F7: 4 | G7: 1 | H7: 1 | I7: =H7/G7 -> 1 | J7: =IFERROR(VLOOKUP(C7,'Q2 Data'!$Y$3:$Z$12,2,FALSE),"") -> 9295.44 | K7: =IFERROR(VLOOKUP(C7,'Q2 Data'!$P$3:$R$14,3,FALSE),"") | O7: 9295 | P7: 15000 | Q7: Transferred from Josh S. Bell Flight directed. First order is not going well.
A8: Assigned | B8: GE MDS LLC | C8: GE Medical Systems Information Technologies, Inc | D8: 1 | E8: 3 | F8: 3 | G8: 5 | H8: 0 | I8: =H8/G8 -> 0 | J8: =IFERROR(VLOOKUP(C8,'Q2 Data'!$Y$3:$Z$12,2,FALSE),"") -> 1140 | K8: =IFERROR(VLOOKUP(C8,'Q2 Data'!$P$3:$R$14,3,FALSE),"") -> 1117.8882 | L8: =J8/K8 -> 1.01978 | N8: GE Vernova. Staying in front of them. Working to get visibility/ RFQs. Working to recover from past business. Old $50K order from 2022 without a hard copy of a PO. | P8: 5000 | Q8: Working to get them on the phone more. Expect things to pick up in summer. Also related to GE MDS. Providing good feedback.
A9: Assigned | B9: Eastman Kodak Company | C9: EASTMAN KODAK COMPANY | D9: 3 | E9: 5 | F9: 6 | G9: 4 | H9: 0 | I9: =H9/G9 -> 0 | J9: =IFERROR(VLOOKUP(C9,'Q2 Data'!$Y$3:$Z$12,2,FALSE),"") | K9: =IFERROR(VLOOKUP(C9,'Q2 Data'!$P$3:$R$14,3,FALSE),"") -> 800 | L9: =J9/K9 -> #VALUE! | N9: Most projects were covered thru Q4. Several brokers are approved, but want to really just work with Astute. Ramp up expected in Q2. Open order $15K, just need to find stock. Focusing on shortages. Also potential in Canada. | P9: 15000 | Q9: Big focus for Q2. Working to get a BOM. Supposted to be getting close to needing to buy. Dayton & Rochester.
A10: Assigned | B10: noLimits Enterprises Inc (dba Radenso) | C10: noLimits Enterprises Inc. dba Radenso | D10: 1 | E10: 3 | F10: 7 | G10: 2 | H10: 0 | I10: =H10/G10 -> 0 | J10: =IFERROR(VLOOKUP(C10,'Q2 Data'!$Y$3:$Z$12,2,FALSE),"") | K10: =IFERROR(VLOOKUP(C10,'Q2 Data'!$P$3:$R$14,3,FALSE),"") -> 19307.12 | L10: =J10/K10 -> #VALUE! | N10: $20K Shipping out in Jan. Police scanners and targets. Big time is black Friday. Now have the cash to build. Radars are expecting to take off. Expecting a monthly demand. CM or noLimits will buy. Working to identify full potential. Love appreciate quick response. | P10: =VLOOKUP(B10,'GP Targets - Q2 2026'!$A:$D,4,FALSE) -> 0 | Q10: Hit or miss. Recently quoted memory, but bought directly with franchise. Work with several CMs.Stay in fromt of them until they ar ready to buy.
A11: Assigned | B11: Ontic | D11: 1 | E11: 3 | F11: 6 | G11: 0 | H11: 0 | J11: =IFERROR(VLOOKUP(C11,'Q2 Data'!$Y$3:$Z$12,2,FALSE),"") | K11: =IFERROR(VLOOKUP(C11,'Q2 Data'!$P$3:$R$14,3,FALSE),"") | N11: Working to get our first order. Quote feedback was that they found stock interally. Inherited stock from Honeywell… Need more stock with demand ramps up. They work with other brokers and CMs. Working to gain more info on compeition and CMs. | P11: =VLOOKUP(B11,'GP Targets - Q2 2026'!$A:$D,4,FALSE) -> 0 | Q11: Now based on suppliers, Lily is our main point of contact. UK has good business with them. Liz working to meet with them in May.
A12: Assigned | B12: Bell Flight Textron Inc. | D12: 2 | E12: 5 | F12: 2 | G12: 0 | H12: 0 | J12: =IFERROR(VLOOKUP(C12,'Q2 Data'!$Y$3:$Z$12,2,FALSE),"") | K12: =IFERROR(VLOOKUP(C12,'Q2 Data'!$P$3:$R$14,3,FALSE),"") | N12: Working to schedule an Audit in Austin. Focus is to sell franchise lines. Mark had a good relationship with Dave (obsolete engineer). | P12: =VLOOKUP(B12,'GP Targets - Q2 2026'!$A:$D,4,FALSE) -> 0 | Q12: When the time is right, consider a site visit. Working with the obsolete team. Located in Dallas. Able to schedule a lunch?
A13: Assigned | B13: Canyon AeroConnect | D13: 6 | E13: 6 | F13: 1 | G13: 0 | H13: 0 | J13: =IFERROR(VLOOKUP(C13,'Q2 Data'!$Y$3:$Z$12,2,FALSE),"") | K13: =IFERROR(VLOOKUP(C13,'Q2 Data'!$P$3:$R$14,3,FALSE),"") | N13: Working to get one order this quarter. They work closely with one broker. Will only give us a shot if the other broker can't deliver. Related to Blue Wave? | P13: =VLOOKUP(B13,'GP Targets - Q2 2026'!$A:$D,4,FALSE) -> 0 | Q13: DROP - Potential but not interested in adding another broker at this time.
A14: Assigned | B14: GE Vernova (Energy Businesses) | D14: 1 | E14: 7 | F14: 0 | G14: 0 | H14: 0 | J14: =IFERROR(VLOOKUP(C14,'Q2 Data'!$Y$3:$Z$12,2,FALSE),"") | K14: =IFERROR(VLOOKUP(C14,'Q2 Data'!$P$3:$R$14,3,FALSE),"") | N14: GE Vernova. | P14: =VLOOKUP(B14,'GP Targets - Q2 2026'!$A:$D,4,FALSE) -> 0
A15: Assigned | B15: SensIT | D15: 1 | E15: 6 | F15: 0 | G15: 0 | H15: 0 | J15: =IFERROR(VLOOKUP(C15,'Q2 Data'!$Y$3:$Z$12,2,FALSE),"") | K15: =IFERROR(VLOOKUP(C15,'Q2 Data'!$P$3:$R$14,3,FALSE),"") | N15: $3.3K inv 2025. Continue to try and gain interest with Buyer. Continue to keep on Watch List for now. | P15: =VLOOKUP(B15,'GP Targets - Q2 2026'!$A:$D,4,FALSE) -> 0 | Q15: Keep
A16: Assigned | B16: S&B Industry, Inc. | C16: S&B INDUSTRY, INC | D16: 1 | E16: 4 | F16: 0 | G16: 0 | H16: 0 | J16: =IFERROR(VLOOKUP(C16,'Q2 Data'!$Y$3:$Z$12,2,FALSE),"") -> 1056.84 | K16: =IFERROR(VLOOKUP(C16,'Q2 Data'!$P$3:$R$14,3,FALSE),"") -> 522.04 | L16: =J16/K16 -> 2.0244426 | P16: =VLOOKUP(B16,'GP Targets - Q2 2026'!$A:$D,4,FALSE) -> 0
A17: Assigned | B17: BENCHMARK ELECTRONICS | D17: 3 | E17: 3 | F17: 0 | G17: 0 | H17: 0 | J17: =IFERROR(VLOOKUP(C17,'Q2 Data'!$Y$3:$Z$12,2,FALSE),"") | K17: =IFERROR(VLOOKUP(C17,'Q2 Data'!$P$3:$R$14,3,FALSE),"") | N17: Have good relationships with the Buyers in AZ. Hoping Mike can get in with Claudia. New PM. Build for Raytheon, and others. Work to get a few RFQs and CQs. | P17: =VLOOKUP(B17,'GP Targets - Q2 2026'!$A:$D,4,FALSE) -> 0 | Q17: DROP - Shutting down at the end of July
A18: Assigned | B18: Mirian Solutions | D18: 1 | E18: 2 | F18: 0 | G18: 0 | H18: 0 | J18: =IFERROR(VLOOKUP(C18,'Q2 Data'!$Y$3:$Z$12,2,FALSE),"") | K18: =IFERROR(VLOOKUP(C18,'Q2 Data'!$P$3:$R$14,3,FALSE),"") | N18: CM for Kodak. Demand is in NY. Trying to get Kodak more incentive to use us. Also, break in to other Mirian projects. Sold $16K in 2025. | P18: =VLOOKUP(B18,'GP Targets - Q2 2026'!$A:$D,4,FALSE) -> 0
A19: Assigned | B19: Emerald EMS | D19: 2 | E19: 1 | F19: 0 | G19: 0 | H19: 0 | J19: =IFERROR(VLOOKUP(C19,'Q2 Data'!$Y$3:$Z$12,2,FALSE),"") | K19: =IFERROR(VLOOKUP(C19,'Q2 Data'!$P$3:$R$14,3,FALSE),"") | N19: 0 | P19: =VLOOKUP(B19,'GP Targets - Q2 2026'!$A:$D,4,FALSE) -> 0 | Q19: DROP - CM for SnapOn
A20: Assigned | B20: Accurate Electronics | D20: 1 | E20: 1 | F20: 0 | G20: 0 | H20: 0 | J20: =IFERROR(VLOOKUP(C20,'Q2 Data'!$Y$3:$Z$12,2,FALSE),"") | K20: =IFERROR(VLOOKUP(C20,'Q2 Data'!$P$3:$R$14,3,FALSE),"") | N20: Same as Qual-Pro (close to Ontic). Work to visit. Smaller, but do not know the potential yet. | P20: =VLOOKUP(B20,'GP Targets - Q2 2026'!$A:$D,4,FALSE) -> 0 | Q20: Account Review - Q1 2026 - Aaron M.pptx
A21: Assigned | B21: Saline Lectronics Manufacturing Services | D21: 1 | E21: 1 | F21: 0 | G21: 0 | H21: 0 | J21: =IFERROR(VLOOKUP(C21,'Q2 Data'!$Y$3:$Z$12,2,FALSE),"") | K21: =IFERROR(VLOOKUP(C21,'Q2 Data'!$P$3:$R$14,3,FALSE),"") | N21: Smaller potential. Purchased by Emerald (bigger potential). Were not able to find stock with the RFQs we received. | P21: =VLOOKUP(B21,'GP Targets - Q2 2026'!$A:$D,4,FALSE) -> 0 | Q21: Keep
A22: Assigned | B22: Acuity Brands | D22: 8 | E22: 0 | F22: 0 | G22: 0 | H22: 0 | J22: =IFERROR(VLOOKUP(C22,'Q2 Data'!$Y$3:$Z$12,2,FALSE),"") | K22: =IFERROR(VLOOKUP(C22,'Q2 Data'!$P$3:$R$14,3,FALSE),"") | N22: Mark was heavily involved. Maybe work to visit Indiana with Josh? Mostly driven out of Mexico. Supplier on record. | P22: =VLOOKUP(B22,'GP Targets - Q2 2026'!$A:$D,4,FALSE) -> 0 | Q22: DROP
A23: Assigned | B23: GE Multilin | D23: 5 | E23: 0 | F23: 0 | G23: 0 | H23: 0 | J23: =IFERROR(VLOOKUP(C23,'Q2 Data'!$Y$3:$Z$12,2,FALSE),"") | K23: =IFERROR(VLOOKUP(C23,'Q2 Data'!$P$3:$R$14,3,FALSE),"") | N23: GE Vernova. | P23: =VLOOKUP(B23,'GP Targets - Q2 2026'!$A:$D,4,FALSE) -> 0
A24: Assigned | B24: Foxconn | D24: 3 | E24: 0 | F24: 0 | G24: 0 | H24: 0 | J24: =IFERROR(VLOOKUP(C24,'Q2 Data'!$Y$3:$Z$12,2,FALSE),"") | K24: =IFERROR(VLOOKUP(C24,'Q2 Data'!$P$3:$R$14,3,FALSE),"") | P24: =VLOOKUP(B24,'GP Targets - Q2 2026'!$A:$D,4,FALSE) -> 0
A25: Assigned | B25: General Motors | D25: 3 | E25: 0 | F25: 0 | G25: 0 | H25: 0 | J25: =IFERROR(VLOOKUP(C25,'Q2 Data'!$Y$3:$Z$12,2,FALSE),"") | K25: =IFERROR(VLOOKUP(C25,'Q2 Data'!$P$3:$R$14,3,FALSE),"") | P25: =VLOOKUP(B25,'GP Targets - Q2 2026'!$A:$D,4,FALSE) -> 0
A26: Assigned | B26: Crane Aerospace & Electronics | D26: 2 | E26: 0 | F26: 0 | G26: 0 | H26: 0 | J26: =IFERROR(VLOOKUP(C26,'Q2 Data'!$Y$3:$Z$12,2,FALSE),"") | K26: =IFERROR(VLOOKUP(C26,'Q2 Data'!$P$3:$R$14,3,FALSE),"") | P26: =VLOOKUP(B26,'GP Targets - Q2 2026'!$A:$D,4,FALSE) -> 0
A27: Assigned | B27: CTCT | D27: 1 | E27: 0 | F27: 0 | G27: 0 | H27: 0 | J27: =IFERROR(VLOOKUP(C27,'Q2 Data'!$Y$3:$Z$12,2,FALSE),"") | K27: =IFERROR(VLOOKUP(C27,'Q2 Data'!$P$3:$R$14,3,FALSE),"") | N27: Wings to Catapillar. Place holder. Morey is doing the buying right now. | P27: =VLOOKUP(B27,'GP Targets - Q2 2026'!$A:$D,4,FALSE) -> 0 | Q27: DROP - LP
A28: Assigned | B28: Mars International Inc. | D28: 1 | E28: 0 | F28: 0 | G28: 0 | H28: 0 | J28: =IFERROR(VLOOKUP(C28,'Q2 Data'!$Y$3:$Z$12,2,FALSE),"") | K28: =IFERROR(VLOOKUP(C28,'Q2 Data'!$P$3:$R$14,3,FALSE),"") | N28: 0 | P28: =VLOOKUP(B28,'GP Targets - Q2 2026'!$A:$D,4,FALSE) -> 0 | Q28: DROP - LP
B30: Total Assigned | E30: =SUM(E3:E28) -> 85 | F30: =SUM(F3:F28) -> 86 | G30: =SUM(G3:G28) -> 41 | H30: =SUM(H3:H28) -> 15 | I30: =IFERROR(H30/G30,"") -> 0.36585366 | J30: =SUM(J3:J28) -> 31916.65 | K30: =SUM(K3:K28) -> 29306.508 | L30: =IFERROR(J30/K30,"") -> 1.0890636 | M30: =K30/#REF! -> #REF! | O30: =SUM(O3:O28) -> 91661 | P30: =SUM(P3:P28) -> 190000
A32: Not Assigned | B32: Astro Geo Marine, Inc. | E32: =IFERROR(VLOOKUP(B32,'Q2 Data'!A:B,2,FALSE),"0") -> 1 | F32: =IFERROR(VLOOKUP(B32,'Q2 Data'!E:F,2,FALSE),"0") -> 0 | G32: =IFERROR(VLOOKUP(B32,'Q2 Data'!I:J,2,FALSE),"0") -> 0 | H32: =IFERROR(VLOOKUP(B32,'Q2 Data'!L:M,2,FALSE),"0") -> 0 | I32: =H32/G32 -> #DIV/0! | J32: =IFERROR(VLOOKUP(C32,'Q2 Data'!$Y$3:$Z$12,2,FALSE),"") | K32: =IFERROR(VLOOKUP(C32,'Q2 Data'!$P$3:$R$14,3,FALSE),"") | N32: =IFERROR(VLOOKUP(B32,'Aaron - Q1 2026'!$B$3:$Q$25,16,FALSE),"")
A33: Not Assigned | B33: EMLinQ, LLC | E33: =IFERROR(VLOOKUP(B33,'Q2 Data'!A:B,2,FALSE),"0") -> 3 | F33: =IFERROR(VLOOKUP(B33,'Q2 Data'!E:F,2,FALSE),"0") -> 10 | G33: =IFERROR(VLOOKUP(B33,'Q2 Data'!I:J,2,FALSE),"0") -> 0 | H33: =IFERROR(VLOOKUP(B33,'Q2 Data'!L:M,2,FALSE),"0") -> 0 | I33: =H33/G33 -> #DIV/0! | J33: =IFERROR(VLOOKUP(C33,'Q2 Data'!$Y$3:$Z$12,2,FALSE),"") | K33: =IFERROR(VLOOKUP(C33,'Q2 Data'!$P$3:$R$14,3,FALSE),"") | N33: =IFERROR(VLOOKUP(B33,'Aaron - Q1 2026'!$B$3:$Q$25,16,FALSE),"")
A34: Not Assigned | B34: Firstmark Aerospace Corporation | E34: =IFERROR(VLOOKUP(B34,'Q2 Data'!A:B,2,FALSE),"0") -> 1 | F34: =IFERROR(VLOOKUP(B34,'Q2 Data'!E:F,2,FALSE),"0") -> 0 | G34: =IFERROR(VLOOKUP(B34,'Q2 Data'!I:J,2,FALSE),"0") -> 0 | H34: =IFERROR(VLOOKUP(B34,'Q2 Data'!L:M,2,FALSE),"0") -> 0 | I34: =H34/G34 -> #DIV/0! | J34: =IFERROR(VLOOKUP(C34,'Q2 Data'!$Y$3:$Z$12,2,FALSE),"") | K34: =IFERROR(VLOOKUP(C34,'Q2 Data'!$P$3:$R$14,3,FALSE),"") | N34: =IFERROR(VLOOKUP(B34,'Aaron - Q1 2026'!$B$3:$Q$25,16,FALSE),"")
A35: Not Assigned | B35: IMP Group Ltd. | C35: IMP Group International Inc | E35: =IFERROR(VLOOKUP(B35,'Q2 Data'!A:B,2,FALSE),"0") -> 1 | F35: =IFERROR(VLOOKUP(B35,'Q2 Data'!E:F,2,FALSE),"0") -> 1 | G35: =IFERROR(VLOOKUP(B35,'Q2 Data'!I:J,2,FALSE),"0") -> 1 | H35: =IFERROR(VLOOKUP(B35,'Q2 Data'!L:M,2,FALSE),"0") -> 0 | I35: =H35/G35 -> 0 | J35: =IFERROR(VLOOKUP(C35,'Q2 Data'!$Y$3:$Z$12,2,FALSE),"") | K35: =IFERROR(VLOOKUP(C35,'Q2 Data'!$P$3:$R$14,3,FALSE),"") -> 0 | N35: =IFERROR(VLOOKUP(B35,'Aaron - Q1 2026'!$B$3:$Q$25,16,FALSE),"")
A36: Not Assigned | B36: Motion Industries | E36: =IFERROR(VLOOKUP(B36,'Q2 Data'!A:B,2,FALSE),"0") -> 1 | F36: =IFERROR(VLOOKUP(B36,'Q2 Data'!E:F,2,FALSE),"0") -> 0 | G36: =IFERROR(VLOOKUP(B36,'Q2 Data'!I:J,2,FALSE),"0") -> 0 | H36: =IFERROR(VLOOKUP(B36,'Q2 Data'!L:M,2,FALSE),"0") -> 0 | I36: =H36/G36 -> #DIV/0! | J36: =IFERROR(VLOOKUP(C36,'Q2 Data'!$Y$3:$Z$12,2,FALSE),"") | K36: =IFERROR(VLOOKUP(C36,'Q2 Data'!$P$3:$R$14,3,FALSE),"") | N36: =IFERROR(VLOOKUP(B36,'Aaron - Q1 2026'!$B$3:$Q$25,16,FALSE),"")
A37: Not Assigned | B37: Indak Manufacturing | E37: =IFERROR(VLOOKUP(B37,'Q2 Data'!A:B,2,FALSE),"0") -> 0 | F37: =IFERROR(VLOOKUP(B37,'Q2 Data'!E:F,2,FALSE),"0") -> 5 | G37: =IFERROR(VLOOKUP(B37,'Q2 Data'!I:J,2,FALSE),"0") -> 2 | H37: =IFERROR(VLOOKUP(B37,'Q2 Data'!L:M,2,FALSE),"0") -> 0 | I37: =H37/G37 -> 0 | J37: =IFERROR(VLOOKUP(C37,'Q2 Data'!$Y$3:$Z$12,2,FALSE),"") | K37: =IFERROR(VLOOKUP(C37,'Q2 Data'!$P$3:$R$14,3,FALSE),"") | N37: =IFERROR(VLOOKUP(B37,'Aaron - Q1 2026'!$B$3:$Q$25,16,FALSE),"")
A38: Not Assigned | B38: Advanced Manufacturing Corporation (Penang) Sdn Bhd | E38: =IFERROR(VLOOKUP(B38,'Q2 Data'!A:B,2,FALSE),"0") -> 0 | F38: =IFERROR(VLOOKUP(B38,'Q2 Data'!E:F,2,FALSE),"0") -> 1 | G38: =IFERROR(VLOOKUP(B38,'Q2 Data'!I:J,2,FALSE),"0") -> 2 | H38: =IFERROR(VLOOKUP(B38,'Q2 Data'!L:M,2,FALSE),"0") -> 0 | I38: =H38/G38 -> 0 | J38: =IFERROR(VLOOKUP(C38,'Q2 Data'!$Y$3:$Z$12,2,FALSE),"") | K38: =IFERROR(VLOOKUP(C38,'Q2 Data'!$P$3:$R$14,3,FALSE),"") | N38: =IFERROR(VLOOKUP(B38,'Aaron - Q1 2026'!$B$3:$Q$25,16,FALSE),"")
A39: Not Assigned | B39: Mensor LP | E39: =IFERROR(VLOOKUP(B39,'Q2 Data'!A:B,2,FALSE),"0") -> 0 | F39: =IFERROR(VLOOKUP(B39,'Q2 Data'!E:F,2,FALSE),"0") -> 1 | G39: =IFERROR(VLOOKUP(B39,'Q2 Data'!I:J,2,FALSE),"0") -> 0 | H39: =IFERROR(VLOOKUP(B39,'Q2 Data'!L:M,2,FALSE),"0") -> 0 | I39: =H39/G39 -> #DIV/0! | J39: =IFERROR(VLOOKUP(C39,'Q2 Data'!$Y$3:$Z$12,2,FALSE),"") | K39: =IFERROR(VLOOKUP(C39,'Q2 Data'!$P$3:$R$14,3,FALSE),"") | N39: =IFERROR(VLOOKUP(B39,'Aaron - Q1 2026'!$B$3:$Q$25,16,FALSE),"")
A40: Not Assigned | B40: TechnipFMC | E40: =IFERROR(VLOOKUP(B40,'Q2 Data'!A:B,2,FALSE),"0") -> 0 | F40: =IFERROR(VLOOKUP(B40,'Q2 Data'!E:F,2,FALSE),"0") -> 1 | G40: =IFERROR(VLOOKUP(B40,'Q2 Data'!I:J,2,FALSE),"0") -> 0 | H40: =IFERROR(VLOOKUP(B40,'Q2 Data'!L:M,2,FALSE),"0") -> 0 | I40: =H40/G40 -> #DIV/0! | J40: =IFERROR(VLOOKUP(C40,'Q2 Data'!$Y$3:$Z$12,2,FALSE),"") | K40: =IFERROR(VLOOKUP(C40,'Q2 Data'!$P$3:$R$14,3,FALSE),"") | N40: =IFERROR(VLOOKUP(B40,'Aaron - Q1 2026'!$B$3:$Q$25,16,FALSE),"")
A41: Not Assigned | B41: Flex | E41: =IFERROR(VLOOKUP(B41,'Q2 Data'!A:B,2,FALSE),"0") -> 0 | F41: =IFERROR(VLOOKUP(B41,'Q2 Data'!E:F,2,FALSE),"0") -> 0 | G41: =IFERROR(VLOOKUP(B41,'Q2 Data'!I:J,2,FALSE),"0") -> 2 | H41: =IFERROR(VLOOKUP(B41,'Q2 Data'!L:M,2,FALSE),"0") -> 2 | I41: =H41/G41 -> 1 | J41: =IFERROR(VLOOKUP(C41,'Q2 Data'!$Y$3:$Z$12,2,FALSE),"") | K41: =IFERROR(VLOOKUP(C41,'Q2 Data'!$P$3:$R$14,3,FALSE),"") | N41: =IFERROR(VLOOKUP(B41,'Aaron - Q1 2026'!$B$3:$Q$25,16,FALSE),"")
A42: Not Assigned | B42: Wincomm International Electronics Limited | C42: Wincomm International Electronics Limited | E42: =IFERROR(VLOOKUP(B42,'Q2 Data'!A:B,2,FALSE),"0") -> 0 | F42: =IFERROR(VLOOKUP(B42,'Q2 Data'!E:F,2,FALSE),"0") -> 0 | G42: =IFERROR(VLOOKUP(B42,'Q2 Data'!I:J,2,FALSE),"0") -> 0 | H42: =IFERROR(VLOOKUP(B42,'Q2 Data'!L:M,2,FALSE),"0") -> 0 | I42: =H42/G42 -> #DIV/0! | J42: =IFERROR(VLOOKUP(C42,'Q2 Data'!$Y$3:$Z$12,2,FALSE),"") | K42: =IFERROR(VLOOKUP(C42,'Q2 Data'!$P$3:$R$14,3,FALSE),"") -> 1566.3 | N42: =IFERROR(VLOOKUP(B42,'Aaron - Q1 2026'!$B$3:$Q$25,16,FALSE),"")
...

Sheet Q2 Data
A1: Activities | E1: RFQ | I1: CQ | L1: SOLD | P1: Invoiced Sales | X1: Booked Sales
A2: Contact Activity Bpartner Name | B2: Count | E2: Rfq Bpartner Name | F2: Count | I2: Rfq Bpartner Name | J2: Count | L2: Rfq Bpartner Name | M2: Count | P2: Customer Name | Q2: Revenue | R2: GP | S2: GM% | T2: INV Line Count | U2: GP per Line Count | X2: CO ISE | Y2: Dist Cust Booked | Z2: Booked GP | AA2: CO Number Count | AB2: AVG BK GP
A3: Accurate Electronics | B3: 1 | E3: Morey Corporation | F3: 26 | I3: Alstom | J3: 18 | L3: Alstom | M3: 9 | P3: noLimits Enterprises Inc. dba Radenso | Q3: 94511.95 | R3: 19307.12 | S3: 0.20428232 | T3: 1 | U3: 19307.12 | X3: aaromend | Y3: SPEC BUY WITH NO C00 | Z3: 52499 | AA3: 1 | AB3: 52499
A4: Alstom | B4: 2 | E4: Alstom | F4: 12 | I4: GE MDS LLC | J4: 5 | L4: Flex | M4: 2 | P4: Alstom Transportation Inc. | Q4: 14816 | R4: 6034.61 | S4: 0.40730359 | T4: 3 | U4: 2011.5367 | X4: aaromend | Y4: THE MOREY CORPORATION | Z4: 9374.408 | AA4: 1 | AB4: 9374.408
A5: Astro Geo Marine, Inc. | B5: 1 | E5: EMLinQ, LLC | F5: 10 | I5: Eastman Kodak Company | J5: 4 | L5: GE Healthcare | M5: 2 | P5: Wincomm International Electronics Limited | Q5: 3450 | R5: 1566.3 | S5: 0.454 | T5: 1 | U5: 1566.3 | X5: aaromend | Y5: Projects Unlimited Inc. | Z5: 9295.44 | AA5: 1 | AB5: 9295.44
A6: BENCHMARK ELECTRONICS | B6: 3 | E6: Qual-Pro Corporation | F6: 10 | I6: GE Healthcare | J6: 4 | L6: Qual-Pro Corporation | M6: 2 | P6: Qual-Pro Corporation | Q6: 2062.75 | R6: 1524.85 | S6: 0.73923161 | T6: 2 | U6: 762.425 | X6: aaromend | Y6: Alstom Transport Canada Inc | Z6: 4771 | AA6: 1 | AB6: 4771
A7: Bell Flight Textron Inc. | B7: 5 | E7: GE Healthcare | F7: 9 | I7: Morey Corporation | J7: 4 | L7: Morey Corporation | M7: 1 | P7: GE Medical Systems Information Technologies, Inc | Q7: 1899.81 | R7: 1117.8882 | S7: 0.58842105 | T7: 1 | U7: 1117.8882 | X7: aaromend | Y7: Alstom Transportation Inc. | Z7: 3208 | AA7: 2 | AB7: 1604
A8: Canyon AeroConnect | B8: 6 | E8: noLimits Enterprises Inc (dba Radenso) | F8: 7 | I8: Qual-Pro Corporation | J8: 3 | L8: Projects Unlimited Inc. | M8: 1 | P8: EASTMAN KODAK COMPANY | Q8: 1250 | R8: 800 | S8: 0.64 | T8: 1 | U8: 800 | X8: aaromend | Y8: GE Medical Systems Information Technologies, Inc | Z8: 1140 | AA8: 1 | AB8: 1140
A9: EMLinQ, LLC | B9: 3 | E9: Eastman Kodak Company | F9: 6 | I9: Advanced Manufacturing Corporation (Penang) Sdn Bhd | J9: 2 | P9: S&B INDUSTRY, INC | Q9: 2779.5 | R9: 522.04 | S9: 0.18781795 | T9: 3 | U9: 174.0133 | X9: aaromend | Y9: Alstom Transport Canada Inc. | Z9: 1057.0122 | AA9: 1 | AB9: 1057.0122
A10: Eastman Kodak Company | B10: 5 | E10: Ontic | F10: 6 | I10: Flex | J10: 2 | P10: Analytic Systems | X10: aaromend | Y10: S&B INDUSTRY, INC | Z10: 1056.84 | AA10: 1 | AB10: 1056.84
A11: Emerald EMS | B11: 1 | E11: Indak Manufacturing | F11: 5 | I11: Indak Manufacturing | J11: 2 | P11: IMP Group International Inc | X11: aaromend | Y11: Qual-Pro Corporation | Z11: 2013.95 | AA11: 2 | AB11: 1006.975
A12: Firstmark Aerospace Corporation | B12: 1 | E12: Projects Unlimited Inc. | F12: 4 | I12: noLimits Enterprises Inc (dba Radenso) | J12: 2 | P12: Peraton - USPS Central Repair Facility | X12: Total | Z12: 84415.65 | AA12: 11 | AB12: 7674.15
A13: GE Healthcare | B13: 12 | E13: GE MDS LLC | F13: 3 | I13: IMP Group Ltd. | J13: 1 | P13: Swarco McCain, Inc.
A14: GE MDS LLC | B14: 3 | E14: Bell Flight Textron Inc. | F14: 2 | I14: Projects Unlimited Inc. | J14: 1 | P14: THE MOREY CORPORATION
A15: GE Vernova (Energy Businesses) | B15: 7 | E15: Advanced Manufacturing Corporation (Penang) Sdn Bhd | F15: 1 | P15: Total | Q15: 120770.01 | R15: 30872.808 | S15: 0.25563307 | T15: 12 | U15: 2572.734
A16: IMP Group Ltd. | B16: 1 | E16: Canyon AeroConnect | F16: 1
A17: Mirian Solutions | B17: 2 | E17: IMP Group Ltd. | F17: 1
A18: Morey Corporation | B18: 15 | E18: Mensor LP | F18: 1
A19: Motion Industries | B19: 1 | E19: TechnipFMC | F19: 1
A20: Ontic | B20: 3
A21: Projects Unlimited Inc. | B21: 5
A22: Qual-Pro Corporation | B22: 1
A23: S&B Industry, Inc. | B23: 4
A24: Saline Lectronics Manufacturing Services | B24: 1
A25: SensIT | B25: 6
A26: noLimits Enterprises Inc (dba Radenso) | B26: 3
A39: Accurate Electronics
A40: Alstom
A41: Astro Geo Marine, Inc.
A42: BENCHMARK ELECTRONICS
A43: Bell Flight Textron Inc.
A44: Canyon AeroConnect
A45: EMLinQ, LLC
A46: Eastman Kodak Company
A47: Emerald EMS
A48: Firstmark Aerospace Corporation
A49: GE Healthcare
A50: GE MDS LLC
... A67: Flex

Sheet GP Targets - Q1 2026
A1: Account (OT) | B1: Q4 2025 Notes | C1: Scheduled GP Q1 26 | D1: Q1 26 GP Target | E1: If drop - Reason
A2: noLimits Enterprises Inc (dba Radenso) | C2: 20000 | D2: 40000
A3: Alstom | C3: 7000 | D3: 20000
A4: Wincomm International | C4: 2000 | D4: 5000
A5: Eastman Kodak Company | C5: 1000 | D5: 20000
A6: Qual-Pro Corporation | D6: 15000
A7: Morey Corporation | D7: 10000
A8: General Motors LLC | D8: 0
A9: Accurate Electronics | D9: 2500
A10: Acuity Brands | D10: 0
A11: Bell Flight Textron Inc. | D11: 0
A12: BENCHMARK ELECTRONICS | D12: 0
A13: Canyon AeroConnect | D13: 2500
A14: CTCT | D14: 0
A15: Emerald EMS | B15: Connected to Saline. | D15: 0
A16: GE Healthcare | D16: 0
A17: GE MDS LLC | D17: 0
A18: GE Multilin | B18: Related to GE Vernova | D18: 0
A19: GE Vernova (Energy Businesses) | D19: 0
A20: Mars International Inc. | B20: CM for nonlimits, likely a smaller CM. | D20: 0
A21: Mirian Solutions | D21: 0
A22: Ontic | D22: 5000
A23: Saline Lectronics Manufacturing Services | D23: 0
A24: SensIT | B24: Watch List | D24: 0
A25: Trimble Inc. | D25: 0
B27: Scheduled GP 12/30/25 | C27: =SUM(C2:C25) -> 30000 | D27: =SUM(D2:D25) -> 120000
B28: GP Goal Q1 2026 | C28: 120000 | D28: =D27-C28 -> 0

Sheet Aaron - Q1 2026
A1: Q4 2025 | O1: Q1 2026
A2: Status | B2: Account (OT) | C2: Account INFOR | D2: Locations | E2: Activities | F2: RFQ Lines | G2: CQ Lines | H2: CQ Lines Won | I2: Conversion Rate | J2: Booked GP | K2: Invoiced GP | L2: B to I | M2: % of Inv Total | N2: Q4 2025 Notes | O2: Scheduled GP | P2: GP Target | Q2: Q1 2026 Strategy
A3: Assigned | B3: noLimits Enterprises Inc (dba Radenso) | C3: noLimits Enterprises Inc (dba Radenso) | D3: 1 | E3: 9 | F3: 0 | G3: 0 | H3: 0 | I3: =IFERROR(H3/G3,"") | J3: 0 | K3: 0 | L3: =IFERROR(J3/K3,"") | M3: =IFERROR(K3/#REF!,"") | P3: =VLOOKUP(B3,'GP Targets - Q1 2026'!$A:$D,4,FALSE) -> 40000 | Q3: $20K Shipping out in Jan. Police scanners and targets. Big time is black Friday. Now have the cash to build. Radars are expecting to take off. Expecting a monthly demand. CM or noLimits will buy. Working to identify full potential. Love appreciate quick response.
A4: Assigned | B4: Alstom | C4: Alstom Transportation Inc. | D4: 2 | E4: 27 | F4: 13 | G4: 18 | H4: 6 | I4: =IFERROR(H4/G4,"") -> 0.33333333 | J4: 138319.56 | K4: 54048 | L4: =IFERROR(J4/K4,"") -> 2.5591985 | M4: =IFERROR(K4/#REF!,"") | O4: 6851.2 | P4: =VLOOKUP(B4,'GP Targets - Q1 2026'!$A:$D,4,FALSE) -> 20000 | Q4: Sold them ovens. Astute is now a pass thru. Purchasing department is all by projects and 'hand to mouth'. Very small, but able to pay the markups. Good traction with one Buyer. Vendor consolidation is the big focus. Working for a site in IL. 12+ Buyers.
A5: Assigned | B5: Eastman Kodak Company | C5: Eastman Kodak Company | D5: 3 | E5: 19 | F5: 18 | G5: 14 | H5: 8 | I5: =IFERROR(H5/G5,"") -> 0.57142857 | J5: 24778.758 | K5: 23978.758 | L5: =IFERROR(J5/K5,"") -> 1.0333629 | M5: =IFERROR(K5/#REF!,"") | O5: 800 | P5: =VLOOKUP(B5,'GP Targets - Q1 2026'!$A:$D,4,FALSE) -> 20000 | Q5: Most projects were covered thru Q4. Several brokers are approved, but want to really just work with Astute. Ramp up expected in Q2. Open order $15K, just need to find stock. Focusing on shortages. Also potential in Canada.
A6: Assigned | B6: Qual-Pro Corporation | C6: Qual-Pro Corporation | D6: 1 | E6: 14 | F6: 4 | G6: 5 | H6: 3 | I6: =IFERROR(H6/G6,"") -> 0.6 | J6: 750 | K6: 16534.297 | L6: =IFERROR(J6/K6,"") -> 0.045360258 | M6: =IFERROR(K6/#REF!,"") | O6: 750 | P6: =VLOOKUP(B6,'GP Targets - Q1 2026'!$A:$D,4,FALSE) -> 15000 | Q6: Related to Ontic. L3 is one of their customers. Leveraging Ontic.
A7: Assigned | B7: Morey Corporation | C7: THE MOREY CORPORATION | D7: 1 | E7: 17 | F7: 106 | G7: 2 | H7: 2 | I7: =IFERROR(H7/G7,"") -> 1 | J7: 15449.5 | K7: 21372.752 | L7: =IFERROR(J7/K7,"") -> 0.72285965 | M7: =IFERROR(K7/#REF!,"") | P7: =VLOOKUP(B7,'GP Targets - Q1 2026'!$A:$D,4,FALSE) -> 10000 | Q7: Prioritized net terms with them. Making sure they pay on time. Analog Devices have a large price increase coming, looking to see how we can help them keep costs down. Also, TI is in a smiliar boat.
A8: Assigned | B8: Ontic | C8: Ontic | D8: 3 | E8: 45 | F8: 12 | G8: 8 | H8: 0 | I8: =IFERROR(H8/G8,"") -> 0 | J8: 0 | K8: 0 | L8: =IFERROR(J8/K8,"") | M8: =IFERROR(K8/#REF!,"") | P8: =VLOOKUP(B8,'GP Targets - Q1 2026'!$A:$D,4,FALSE) -> 5000 | Q8: Working to get our first order. Quote feedback was that they found stock interally. Inherited stock from Honeywell… Need more stock with demand ramps up. They work with other brokers and CMs. Working to gain more info on compeition and CMs.
A9: Assigned | B9: Accurate Electronics | C9: Accurate Electronics | D9: 1 | E9: 9 | F9: 1 | G9: 1 | H9: 0 | I9: =IFERROR(H9/G9,"") -> 0 | J9: 0 | K9: 0 | L9: =IFERROR(J9/K9,"") | M9: =IFERROR(K9/#REF!,"") | P9: =VLOOKUP(B9,'GP Targets - Q1 2026'!$A:$D,4,FALSE) -> 2500 | Q9: Same as Qual-Pro (close to Ontic). Work to visit. Smaller, but do not know the potential yet.
A10: Assigned | B10: Canyon AeroConnect | C10: Canyon AeroConnect | D10: 1 | E10: 5 | F10: 0 | G10: 0 | H10: 0 | I10: =IFERROR(H10/G10,"") | J10: 0 | K10: 0 | L10: =IFERROR(J10/K10,"") | M10: =IFERROR(K10/#REF!,"") | N10: Mil-aero | P10: =VLOOKUP(B10,'GP Targets - Q1 2026'!$A:$D,4,FALSE) -> 2500 | Q10: Working to get one order this quarter. They work closely with one broker. Will only give us a shot if the other broker can't deliver. Related to Blue Wave?
A11: Assigned | B11: General Motors LLC | C11: General Motors LLC | D11: 3 | E11: 12 | F11: 1349 | G11: 253 | H11: 250 | I11: =IFERROR(H11/G11,"") -> 0.98814229 | J11: 37072296 | K11: 0 | L11: =IFERROR(J11/K11,"") | M11: =IFERROR(K11/#REF!,"") | P11: =VLOOKUP(B11,'GP Targets - Q1 2026'!$A:$D,4,FALSE) -> 0 | Q11: Working to invoice what was booked.
A12: Assigned | B12: Acuity Brands | C12: Acuity Brands | D12: 6 | E12: 12 | F12: 2 | G12: 1 | H12: 1 | I12: =IFERROR(H12/G12,"") -> 1 | J12: 0 | K12: 0 | L12: =IFERROR(J12/K12,"") | M12: =IFERROR(K12/#REF!,"") | P12: =VLOOKUP(B12,'GP Targets - Q1 2026'!$A:$D,4,FALSE) -> 0 | Q12: Mark was heavily involved. Maybe work to visit Indiana with Josh? Mostly driven out of Mexico. Supplier on record.
A13: Assigned | B13: GE MDS LLC | C13: GE MDS LLC | D13: 1 | E13: 8 | F13: 5 | G13: 3 | H13: 0 | I13: =IFERROR(H13/G13,"") -> 0 | J13: 0 | K13: 0 | L13: =IFERROR(J13/K13,"") | M13: =IFERROR(K13/#REF!,"") | P13: =VLOOKUP(B13,'GP Targets - Q1 2026'!$A:$D,4,FALSE) -> 0 | Q13: GE Vernova. Staying in front of them. Working to get visibility/ RFQs. Working to recover from past business. Old $50K order from 2022 without a hard copy of a PO.
A14: Assigned | B14: GE Multilin | C14: GE Multilin | D14: 5 | E14: 6 | F14: 1 | G14: 0 | H14: 0 | I14: =IFERROR(H14/G14,"") | J14: 0 | K14: 0 | L14: =IFERROR(J14/K14,"") | M14: =IFERROR(K14/#REF!,"") | N14: Related to GE Vernova | P14: =VLOOKUP(B14,'GP Targets - Q1 2026'!$A:$D,4,FALSE) -> 0 | Q14: GE Vernova.
A15: Assigned | B15: Mirian Solutions | C15: Mirian Solutions | D15: 1 | E15: 6 | F15: 1 | G15: 0 | H15: 0 | I15: =IFERROR(H15/G15,"") | J15: 0 | K15: 0 | L15: =IFERROR(J15/K15,"") | M15: =IFERROR(K15/#REF!,"") | P15: =VLOOKUP(B15,'GP Targets - Q1 2026'!$A:$D,4,FALSE) -> 0 | Q15: CM for Kodak. Demand is in NY. Trying to get Kodak more incentive to use us. Also, break in to other Mirian projects. Sold $16K in 2025.
A16: Assigned | B16: CTCT | C16: CTCT | D16: 2 | E16: 0 | F16: 0 | G16: 0 | H16: 0 | I16: =IFERROR(H16/G16,"") | J16: 0 | K16: 0 | L16: =IFERROR(J16/K16,"") | M16: =IFERROR(K16/#REF!,"") | N16: 0 | P16: =VLOOKUP(B16,'GP Targets - Q1 2026'!$A:$D,4,FALSE) -> 0 | Q16: Wings to Catapillar. Place holder. Morey is doing the buying right now.
A17: Assigned | B17: GE Vernova (Energy Businesses) | C17: GE Vernova (Energy Businesses) | D17: 1 | E17: 17 | F17: 0 | G17: 0 | H17: 0 | I17: =IFERROR(H17/G17,"") | J17: 0 | K17: 0 | L17: =IFERROR(J17/K17,"") | M17: =IFERROR(K17/#REF!,"") | N17: Mapping out sites and verticals. High potential. | P17: =VLOOKUP(B17,'GP Targets - Q1 2026'!$A:$D,4,FALSE) -> 0 | Q17: GE Vernova.
A18: Assigned | B18: GE Healthcare | C18: GE Healthcare | D18: 6 | E18: 6 | F18: 0 | G18: 0 | H18: 0 | I18: =IFERROR(H18/G18,"") | J18: 0 | K18: 0 | L18: =IFERROR(J18/K18,"") | M18: =IFERROR(K18/#REF!,"") | N18: Setup for repairs division. CMs place the orders. | P18: =VLOOKUP(B18,'GP Targets - Q1 2026'!$A:$D,4,FALSE) -> 0 | Q18: Just got approved with their repairs division to get into other Bus.
A19: Assigned | B19: Saline Lectronics Manufacturing Services | C19: Saline Lectronics Manufacturing Services | D19: 1 | E19: 5 | F19: 0 | G19: 0 | H19: 0 | I19: =IFERROR(H19/G19,"") | J19: 0 | K19: 0 | L19: =IFERROR(J19/K19,"") | M19: =IFERROR(K19/#REF!,"") | P19: =VLOOKUP(B19,'GP Targets - Q1 2026'!$A:$D,4,FALSE) -> 0 | Q19: Smaller potential. Purchased by Emerald (bigger potential). Were not able to find stock with the RFQs we received.
A20: Assigned | B20: Trimble Inc. | C20: Trimble Inc. | D20: 7 | E20: 5 | F20: 0 | G20: 0 | H20: 0 | I20: =IFERROR(H20/G20,"") | J20: 0 | K20: 0 | L20: =IFERROR(J20/K20,"") | M20: =IFERROR(K20/#REF!,"") | N20: Building for Catapillar. Kristen Rhiner, global commodity manager/ director. | P20: =VLOOKUP(B20,'GP Targets - Q1 2026'!$A:$D,4,FALSE) -> 0 | Q20: Wings to Catapillar. Place holder. Morey is doing the buying right now.
A21: Assigned | B21: Bell Flight Textron Inc. | C21: Bell Flight Textron Inc. | D21: 3 | E21: 3 | F21: 0 | G21: 0 | H21: 0 | I21: =IFERROR(H21/G21,"") | J21: 0 | K21: 0 | L21: =IFERROR(J21/K21,"") | M21: =IFERROR(K21/#REF!,"") | P21: =VLOOKUP(B21,'GP Targets - Q1 2026'!$A:$D,4,FALSE) -> 0 | Q21: Working to schedule an Audit in Austin. Focus is to sell franchise lines. Mark had a good relationship with Dave (obsolete engineer).
A22: Assigned | B22: SensIT | C22: SensIT | D22: 1 | E22: 3 | F22: 0 | G22: 0 | H22: 0 | I22: =IFERROR(H22/G22,"") | J22: 0 | K22: 0 | L22: =IFERROR(J22/K22,"") | M22: =IFERROR(K22/#REF!,"") | N22: Watch List | P22: =VLOOKUP(B22,'GP Targets - Q1 2026'!$A:$D,4,FALSE) -> 0 | Q22: $3.3K inv 2025. Continue to try and gain interest with Buyer. Continue to keep on Watch List for now.
A23: Assigned | B23: BENCHMARK ELECTRONICS | C23: BENCHMARK ELECTRONICS | D23: 2 | E23: 2 | F23: 0 | G23: 0 | H23: 0 | I23: =IFERROR(H23/G23,"") | J23: 0 | K23: 0 | L23: =IFERROR(J23/K23,"") | M23: =IFERROR(K23/#REF!,"") | P23: =VLOOKUP(B23,'GP Targets - Q1 2026'!$A:$D,4,FALSE) -> 0 | Q23: Have good relationships with the Buyers in AZ. Hoping Mike can get in with Claudia. New PM. Build for Raytheon, and others. Work to get a few RFQs and CQs.
A24: Assigned | B24: Emerald EMS | C24: Emerald EMS | D24: 2 | E24: 2 | F24: 0 | G24: 0 | H24: 0 | I24: =IFERROR(H24/G24,"") | J24: 0 | K24: 0 | L24: =IFERROR(J24/K24,"") | M24: =IFERROR(K24/#REF!,"") | N24: Connected to Saline. | P24: =VLOOKUP(B24,'GP Targets - Q1 2026'!$A:$D,4,FALSE) -> 0
A25: Assigned | B25: Mars International Inc. | C25: Mars International Inc. | D25: 1 | E25: 1 | F25: 0 | G25: 0 | H25: 0 | I25: =IFERROR(H25/G25,"") | J25: 0 | K25: 0 | L25: =IFERROR(J25/K25,"") | M25: =IFERROR(K25/#REF!,"") | N25: CM for nonlimits, likely a smaller CM. Leverage approval with Radenso (police scanners). | P25: =VLOOKUP(B25,'GP Targets - Q1 2026'!$A:$D,4,FALSE) -> 0
A27: 23 | B27: Total Assigned | D27: 55 | E27: =SUM(E3:E25) -> 233 | F27: =SUM(F3:F25) -> 1512 | G27: =SUM(G3:G25) -> 305 | H27: =SUM(H3:H25) -> 270 | I27: =IFERROR(H27/G27,"") -> 0.8852459 | J27: =SUM(J3:J25) -> 37251594 | K27: =SUM(K3:K25) -> 115933.81 | L27: =IFERROR(J27/K27,"") -> 321.31778 | M27: =K27/#REF! -> #REF! | O27: =SUM(O3:O25) -> 8401.2 | P27: =SUM(P3:P25) -> 115000
A29: Not Assigned | B29: Motion Industries | C29: MOTION INDUSTRIES, INC. | E29: 2 | F29: 0 | G29: 0 | H29: 0 | I29: =IFERROR(H29/G29,"") | J29: 400 | K29: 0 | L29: =IFERROR(J29/K29,"") | O29: 400
A30: Not Assigned | B30: FMC Technologies Measurement Solutions Inc. | C30: FMC Technologies Measurement Solutions Inc. | E30: 0 | F30: 0 | G30: 0 | H30: 0 | I30: =IFERROR(H30/G30,"") | J30: 993.28 | K30: 993.28 | L30: =IFERROR(J30/K30,"") -> 1
A31: Not Assigned | B31: Wincomm International Electronics Limited | C31: Wincomm International Electronics Limited | E31: 0 | F31: 0 | G31: 0 | H31: 0 | I31: =IFERROR(H31/G31,"") | J31: 1566.3 | K31: 0 | L31: =IFERROR(J31/K31,"") | O31: 1566.3 | Q31: CM for Kodak, overseas.
A32: Not Assigned | B32: noLimits Enterprises Inc. dba Radenso | C32: noLimits Enterprises Inc. dba Radenso | E32: 0 | F32: 0 | G32: 0 | H32: 0 | I32: =IFERROR(H32/G32,"") | J32: 19575 | K32: 0 | L32: =IFERROR(J32/K32,"") | O32: 19575
A33: Not Assigned | B33: SPEC BUY WITH NO C00 | C33: SPEC BUY WITH NO C00 | E33: 0 | F33: 0 | G33: 0 | H33: 0 | I33: =IFERROR(H33/G33,"") | J33: 515498.81 | K33: 0 | L33: =IFERROR(J33/K33,"")
A34: Not Assigned | B34: Acron Aviation, Inc | C34: Acron Aviation, Inc | E34: 0 | F34: 0 | G34: 0 | H34: 0 | I34: =IFERROR(H34/G34,"") | K34: 3375.2033 | L34: =IFERROR(J34/K34,"") -> 0
A35: Not Assigned | B35: Apollo America Inc. | E35: 5 | F35: 0 | G35: 0 | H35: 0 | I35: =IFERROR(H35/G35,"") | K35: 0 | L35: =IFERROR(J35/K35,"")
A36: Not Assigned | B36: Interalia | E36: 4 | F36: 1 | G36: 1 | H36: 0 | I36: =IFERROR(H36/G36,"") -> 0 | K36: 0 | L36: =IFERROR(J36/K36,"")
A37: Not Assigned | B37: BizLink Technology (S.E.A) Sdn. Bhd. | E37: 3 | F37: 0 | G37: 0 | H37: 0 | I37: =IFERROR(H37/G37,"") | K37: 0 | L37: =IFERROR(J37/K37,"") | Q37: CM for Kodak, overseas.
A38: Not Assigned | B38: EMLinQ, LLC | E38: 3 | F38: 0 | G38: 0 | H38: 0 | I38: =IFERROR(H38/G38,"") | K38: 0 | L38: =IFERROR(J38/K38,"")
A39: Not Assigned | B39: TechnipFMC | E39: 3 | F39: 1 | G39: 1 | H39: 1 | I39: =IFERROR(H39/G39,"") -> 1 | K39: 0 | L39: =IFERROR(J39/K39,"")
A40: Not Assigned | B40: GM INTERNATIONAL SAFETY, INC. | E40: 0 | F40: 544 | G40: 10 | H40: 9 | I40: =IFERROR(H40/G40,"") -> 0.9 | K40: 0 | L40: =IFERROR(J40/K40,"")
A41: Not Assigned | B41: M2S electronique | E41: 0 | F41: 8 | G41: 1 | H41: 0 | I41: =IFERROR(H41/G41,"") -> 0 | K41: 0 | L41: =IFERROR(J41/K41,"")
A42: Not Assigned | B42: Indak Manufacturing | E42: 0 | F42: 1 | G42: 1 | H42: 0 | I42: =IFERROR(H42/G42,"") -> 0 | K42: 0 | L42: =IFERROR(J42/K42,"")
...

Sheet Aaron - 10.02.25
A1: Date Pulled | B1: 45932
A2: Q3 2025 | B2: Goal/ KPI Detail | C2: Actual | D2: Goal/ KPI | E2: % Achieved | F2: Growth QOQ | H2: Last QTR
B3: Invoiced GP | C3: 32980 | D3: 132600 | E3: =C3/D3 -> 0.24871795 | F3: =(C3-H3)/H3 -> 0.31972789 | H3: 24990
B4: Booked GP | C4: 63210 | D4: 132600 | E4: =C4/D4 -> 0.47669683 | F4: =(C4-H4)/H4 -> 0.54812638 | H4: 40830
B5: Conversion Rates | C5: =C6/C7 -> 0.2278481 | D5: =D6/D7 -> 0.3 | E5: =C5/D5 -> 0.75949367 | F5: =(C5-H5)/H5 -> -0.66148282 | H5: =H6/H7 -> 0.67307692
B6: Count CQ Lines Won | C6: 18 | D6: =4.5*13 -> 58.5 | E6: =C6/D6 -> 0.30769231 | F6: =IFERROR((C6-H6)/H6,"") -> -0.74285714 | H6: 70
B7: Count Total CQ Lines | C7: 79 | D7: =15*13 -> 195 | E7: =C7/D7 -> 0.40512821 | F7: =(C7-H7)/H7 -> -0.24038462 | H7: 104
B8: Count RFQ Lines | C8: 319 | D8: =20*13 -> 260 | E8: =C8/D8 -> 1.2269231 | F8: =(C8-H8)/H8 -> -0.38888889 | H8: 522
B9: Count Activities | C9: 1040 | D9: =100*13 -> 1300 | E9: =C9/D9 -> 0.8 | F9: =(C9-H9)/H9 -> 0.79930796 | H9: 578
A11: Q4 2025 | B11: Invoiced GP | C11: 0 | D11: 132600 | E11: =C11/D11 -> 0
B12: Scheduled GP | D12: 132600 | E12: =C12/D12 -> 0
B13: Projected GP | C13: =SUM(C11:C12) -> 0 | D13: 132600 | E13: =C13/D13 -> 0
B14: Assigned Accounts | C14: 35
B15: Assigned Locations | C15: 107
A17: Q3 2025 | M17: Q4 2025
A18: Status | B18: Account | C18: Locations | D18: Activities | E18: RFQ Lines | F18: CQ Lines | G18: CQ Lines Won | H18: Conversion Rate | I18: Booked GP | J18: Invoiced GP | K18: B to I | L18: % of Inv Total | M18: Scheduled GP | N18: Notes
A19: Assigned | B19: Acuity Brands | C19: 6 | D19: 90 | E19: 4 | F19: 5 | G19: 1 | H19: =IFERROR(G19/F19,"") -> 0.2 | I19: 131 | J19: 131 | K19: =IFERROR(I19/J19,"") -> 1 | L19: =IFERROR(J19/$C$3,"") -> 0.0039721043 | M19: 0
A20: Assigned | B20: Alstom | C20: 2 | D20: 61 | E20: 30 | F20: 16 | G20: 4 | H20: =IFERROR(G20/F20,"") -> 0.25 | I20: 2576 | J20: 1550 | K20: =IFERROR(I20/J20,"") -> 1.6619355 | L20: =IFERROR(J20/$C$3,"") -> 0.046998181 | M20: 1026
A21: Assigned | B21: Bell Flight Textron Inc. | C21: 3 | D21: 125 | E21: 52 | F21: 15 | G21: 0 | H21: =IFERROR(G21/F21,"") -> 0 | I21: 0 | J21: 0 | K21: =IFERROR(I21/J21,"") | L21: =IFERROR(J21/$C$3,"") -> 0 | M21: 0
A22: Assigned | B22: BENCHMARK ELECTRONICS | C22: 8 | D22: 25 | E22: 0 | F22: 0 | G22: 0 | H22: =IFERROR(G22/F22,"") | I22: 0 | J22: 0 | K22: =IFERROR(I22/J22,"") | L22: =IFERROR(J22/$C$3,"") -> 0 | M22: 0
A23: Assigned | B23: Canyon AeroConnect | C23: 1 | D23: 23 | E23: 0 | F23: 0 | G23: 0 | H23: =IFERROR(G23/F23,"") | I23: 0 | J23: 0 | K23: =IFERROR(I23/J23,"") | L23: =IFERROR(J23/$C$3,"") -> 0 | M23: 0 | N23: Mil-aero
A24: Assigned | B24: Eastman Kodak Company | C24: 3 | D24: 49 | E24: 7 | F24: 6 | G24: 2 | H24: =IFERROR(G24/F24,"") -> 0.33333333 | I24: 1004 | J24: 1000 | K24: =IFERROR(I24/J24,"") -> 1.004 | L24: =IFERROR(J24/$C$3,"") -> 0.030321407 | M24: 0
A25: Assigned | B25: Emerald EMS | C25: 2 | D25: 6 | E25: 0 | F25: 0 | G25: 0 | H25: =IFERROR(G25/F25,"") | I25: 0 | J25: 0 | K25: =IFERROR(I25/J25,"") | L25: =IFERROR(J25/$C$3,"") -> 0 | M25: 0 | N25: Connected to Saline.
A26: Assigned | B26: GE Healthcare | C26: 6 | D26: 8 | E26: 0 | F26: 0 | G26: 0 | H26: =IFERROR(G26/F26,"") | I26: 0 | J26: 0 | K26: =IFERROR(I26/J26,"") | L26: =IFERROR(J26/$C$3,"") -> 0 | M26: 0 | N26: Setup for repairs division. CMs place the orders. Hugo BD.
A27: Assigned | B27: GE MDS LLC | C27: 1 | D27: 40 | E27: 4 | F27: 5 | G27: 0 | H27: =IFERROR(G27/F27,"") -> 0 | I27: 0 | J27: 0 | K27: =IFERROR(I27/J27,"") | L27: =IFERROR(J27/$C$3,"") -> 0 | M27: 0
A28: Assigned | B28: General Motors | C28: 3 | D28: 5 | E28: 1 | F28: 3 | G28: 0 | H28: =IFERROR(G28/F28,"") -> 0 | I28: 0 | J28: 0 | K28: =IFERROR(I28/J28,"") | L28: =IFERROR(J28/$C$3,"") -> 0 | M28: 0
A29: Assigned | B29: Mars International Inc. | C29: 1 | D29: 4 | E29: 0 | F29: 0 | G29: 0 | H29: =IFERROR(G29/F29,"") | I29: 0 | J29: 0 | K29: =IFERROR(I29/J29,"") | L29: =IFERROR(J29/$C$3,"") -> 0 | M29: 0 | N29: CM for nonlimits, likely a smaller CM. Leverage approval with Radenso (police scanners).
A30: Assigned | B30: Mirian Solutions | C30: 1 | D30: 11 | E30: 1 | F30: 6 | G30: 6 | H30: =IFERROR(G30/F30,"") -> 1 | I30: 293 | J30: 10640 | K30: =IFERROR(I30/J30,"") -> 0.027537594 | L30: =IFERROR(J30/$C$3,"") -> 0.32261977 | M30: 0
A31: Assigned | B31: Morey Corporation | C31: 1 | D31: 66 | E31: 5 | F31: 6 | G31: 2 | H31: =IFERROR(G31/F31,"") -> 0.33333333 | I31: 32010 | J31: 9450 | K31: =IFERROR(I31/J31,"") -> 3.3873016 | L31: =IFERROR(J31/$C$3,"") -> 0.2865373 | M31: 32010
A32: Assigned | B32: noLimits Enterprises Inc (dba Radenso) | C32: 1 | D32: 20 | E32: 6 | F32: 1 | G32: 0 | H32: =IFERROR(G32/F32,"") -> 0 | I32: 0 | J32: 0 | K32: =IFERROR(I32/J32,"") | L32: =IFERROR(J32/$C$3,"") -> 0 | M32: 0
A33: Assigned | B33: Ontic | C33: 3 | D33: 55 | E33: 1 | F33: 1 | G33: 0 | H33: =IFERROR(G33/F33,"") -> 0 | I33: 0 | J33: 0 | K33: =IFERROR(I33/J33,"") | L33: =IFERROR(J33/$C$3,"") -> 0 | M33: 0
A34: Assigned | B34: Qual-Pro Corporation | C34: 1 | D34: 31 | E34: 3 | F34: 2 | G34: 2 | H34: =IFERROR(G34/F34,"") -> 1 | I34: 21950 | J34: 5200 | K34: =IFERROR(I34/J34,"") -> 4.2211538 | L34: =IFERROR(J34/$C$3,"") -> 0.15767132 | M34: 21950
A35: Assigned | B35: Saline Lectronics Manufacturing Services | C35: 1 | D35: 40 | E35: 3 | F35: 3 | G35: 0 | H35: =IFERROR(G35/F35,"") -> 0 | I35: 0 | J35: 0 | K35: =IFERROR(I35/J35,"") | L35: =IFERROR(J35/$C$3,"") -> 0 | M35: 0
A36: Assigned | B36: SensIT | C36: 1 | D36: 8 | E36: 0 | F36: 0 | G36: 0 | H36: =IFERROR(G36/F36,"") | I36: 0 | J36: 0 | K36: =IFERROR(I36/J36,"") | L36: =IFERROR(J36/$C$3,"") -> 0 | M36: 0 | N36: Watch List
A37: Assigned | B37: CTCT | C37: 2 | D37: 2 | E37: 0 | F37: 0 | G37: 0 | H37: =IFERROR(G37/F37,"") | I37: 0 | J37: 0 | K37: =IFERROR(I37/J37,"") | L37: =IFERROR(J37/$C$3,"") -> 0 | M37: 0
A38: Assigned | B38: Trimble Inc. | C38: 7 | D38: 6 | E38: 0 | F38: 0 | G38: 0 | H38: =IFERROR(G38/F38,"") | I38: 0 | J38: 0 | K38: =IFERROR(I38/J38,"") | L38: =IFERROR(J38/$C$3,"") -> 0 | M38: 0 | N38: Building for Catapillar. Kristen Rhiner, global commodity manager/ director.
A39: Assigned | B39: GE Multilin | C39: 5 | D39: 20 | E39: 0 | F39: 0 | G39: 0 | H39: =IFERROR(G39/F39,"") | I39: 0 | J39: 0 | K39: =IFERROR(I39/J39,"") | L39: =IFERROR(J39/$C$3,"") -> 0 | M39: 0 | N39: Related to GE Vernova
A40: Assigned | B40: GE Vernova (Energy Businesses) | C40: 1 | D40: 151 | E40: 1 | F40: 0 | G40: 0 | H40: =IFERROR(G40/F40,"") | I40: 0 | J40: 0 | K40: =IFERROR(I40/J40,"") | L40: =IFERROR(J40/$C$3,"") -> 0 | M40: 0 | N40: Mapping out sites and verticals. High potential.
A41: Assigned | B41: Analytic Systems | C41: 1 | D41: 5 | E41: 0 | F41: 0 | G41: 0 | H41: =IFERROR(G41/F41,"") | I41: 0 | J41: 0 | K41: =IFERROR(I41/J41,"") | L41: =IFERROR(J41/$C$3,"") -> 0 | M41: 0 | N41: Traded to James.
A42: Assigned | B42: Axiom Electronics | C42: 1 | D42: 7 | E42: 0 | F42: 0 | G42: 0 | H42: =IFERROR(G42/F42,"") | I42: 0 | J42: 0 | K42: =IFERROR(I42/J42,"") | L42: =IFERROR(J42/$C$3,"") -> 0 | M42: 0 | N42: Traded to James. Buy frequently.
...
